2024-12-18 02:27:08.031305
Traceback (most recent call last):
  File "C:\Users\CFO Tech\source\repos\lucaschess\lucaschessR6\bin\Code\MainWindow\WBase.py", line 370, in run_action
    self.manager.run_action(self.sender().key)
  File "C:\Users\CFO Tech\source\repos\lucaschess\lucaschessR6\bin\Code\Procesador.py", line 583, in run_action
    self.menu_tools()
  File "C:\Users\CFO Tech\source\repos\lucaschess\lucaschessR6\bin\Code\Procesador.py", line 825, in menu_tools
    self.menuTools_run(resp)
  File "C:\Users\CFO Tech\source\repos\lucaschess\lucaschessR6\bin\Code\Procesador.py", line 861, in menuTools_run
    self.visor_remote_pgn()
  File "C:\Users\CFO Tech\source\repos\lucaschess\lucaschessR6\bin\Code\Procesador.py", line 1056, in visor_remote_pgn
    json_pgns = ChessDotComService.get_user_pgns(user_name,date)
                ^^^^^^^^^^^^^^^^^^^^^^^^^^^^^^^^
AttributeError: module 'Code.Services.ChessDotComService' has no attribute 'get_user_pgns'
2024-12-18 02:30:05.690225
Traceback (most recent call last):
  File "C:\Users\CFO Tech\source\repos\lucaschess\lucaschessR6\bin\Code\MainWindow\WBase.py", line 370, in run_action
    self.manager.run_action(self.sender().key)
  File "C:\Users\CFO Tech\source\repos\lucaschess\lucaschessR6\bin\Code\Procesador.py", line 583, in run_action
    self.menu_tools()
  File "C:\Users\CFO Tech\source\repos\lucaschess\lucaschessR6\bin\Code\Procesador.py", line 825, in menu_tools
    self.menuTools_run(resp)
  File "C:\Users\CFO Tech\source\repos\lucaschess\lucaschessR6\bin\Code\Procesador.py", line 861, in menuTools_run
    self.visor_remote_pgn()
  File "C:\Users\CFO Tech\source\repos\lucaschess\lucaschessR6\bin\Code\Procesador.py", line 1056, in visor_remote_pgn
    json_pgns = ChessDotComService.get_user_pgns(user_name,date)
                ^^^^^^^^^^^^^^^^^^^^^^^^^^^^^^^^
AttributeError: module 'Code.Services.ChessDotComService' has no attribute 'get_user_pgns'
2024-12-18 02:35:06.293212
Traceback (most recent call last):
  File "C:\Users\CFO Tech\source\repos\lucaschess\lucaschessR6\bin\Code\MainWindow\WBase.py", line 370, in run_action
    self.manager.run_action(self.sender().key)
  File "C:\Users\CFO Tech\source\repos\lucaschess\lucaschessR6\bin\Code\Procesador.py", line 583, in run_action
    self.menu_tools()
  File "C:\Users\CFO Tech\source\repos\lucaschess\lucaschessR6\bin\Code\Procesador.py", line 825, in menu_tools
    self.menuTools_run(resp)
  File "C:\Users\CFO Tech\source\repos\lucaschess\lucaschessR6\bin\Code\Procesador.py", line 861, in menuTools_run
    self.visor_remote_pgn()
  File "C:\Users\CFO Tech\source\repos\lucaschess\lucaschessR6\bin\Code\Procesador.py", line 1056, in visor_remote_pgn
    json_pgns = ChessDotComService.get_user_pgns(user_name,date)
                ^^^^^^^^^^^^^^^^^^^^^^^^^^^^^^^^
AttributeError: module 'Code.Services.ChessDotComService' has no attribute 'get_user_pgns'
2024-12-18 02:46:56.277733
Traceback (most recent call last):
  File "C:\Users\CFO Tech\source\repos\lucaschess\lucaschessR6\bin\Code\MainWindow\WBase.py", line 370, in run_action
    self.manager.run_action(self.sender().key)
  File "C:\Users\CFO Tech\source\repos\lucaschess\lucaschessR6\bin\Code\Procesador.py", line 583, in run_action
    self.menu_tools()
  File "C:\Users\CFO Tech\source\repos\lucaschess\lucaschessR6\bin\Code\Procesador.py", line 825, in menu_tools
    self.menuTools_run(resp)
  File "C:\Users\CFO Tech\source\repos\lucaschess\lucaschessR6\bin\Code\Procesador.py", line 861, in menuTools_run
    self.visor_remote_pgn()
  File "C:\Users\CFO Tech\source\repos\lucaschess\lucaschessR6\bin\Code\Procesador.py", line 1056, in visor_remote_pgn
    json_pgns = ChessDotComService.get_user_pgns(user_name,date)
                ^^^^^^^^^^^^^^^^^^^^^^^^^^^^^^^^^^^^^^^^^^^^^^^^
TypeError: get_user_pgns() missing 2 required positional arguments: 'year' and 'month'
2024-12-18 02:48:29.630665
Traceback (most recent call last):
  File "C:\Users\CFO Tech\source\repos\lucaschess\lucaschessR6\bin\Code\MainWindow\WBase.py", line 370, in run_action
    self.manager.run_action(self.sender().key)
  File "C:\Users\CFO Tech\source\repos\lucaschess\lucaschessR6\bin\Code\Procesador.py", line 583, in run_action
    self.menu_tools()
  File "C:\Users\CFO Tech\source\repos\lucaschess\lucaschessR6\bin\Code\Procesador.py", line 825, in menu_tools
    self.menuTools_run(resp)
  File "C:\Users\CFO Tech\source\repos\lucaschess\lucaschessR6\bin\Code\Procesador.py", line 861, in menuTools_run
    self.visor_remote_pgn()
  File "C:\Users\CFO Tech\source\repos\lucaschess\lucaschessR6\bin\Code\Procesador.py", line 1056, in visor_remote_pgn
    json_pgns = ChessDotComService.get_user_pgns(user_name,date)
                ^^^^^^^^^^^^^^^^^^^^^^^^^^^^^^^^^^^^^^^^^^^^^^^^
TypeError: get_user_pgns() missing 1 required positional argument: 'date'
2024-12-18 02:50:20.733444
Traceback (most recent call last):
  File "C:\Users\CFO Tech\source\repos\lucaschess\lucaschessR6\bin\Code\MainWindow\WBase.py", line 370, in run_action
    self.manager.run_action(self.sender().key)
  File "C:\Users\CFO Tech\source\repos\lucaschess\lucaschessR6\bin\Code\Procesador.py", line 583, in run_action
    self.menu_tools()
  File "C:\Users\CFO Tech\source\repos\lucaschess\lucaschessR6\bin\Code\Procesador.py", line 825, in menu_tools
    self.menuTools_run(resp)
  File "C:\Users\CFO Tech\source\repos\lucaschess\lucaschessR6\bin\Code\Procesador.py", line 861, in menuTools_run
    self.visor_remote_pgn()
  File "C:\Users\CFO Tech\source\repos\lucaschess\lucaschessR6\bin\Code\Procesador.py", line 1056, in visor_remote_pgn
    json_pgns = ChessDotComService.get_user_pgns(user_name,date)
                ^^^^^^^^^^^^^^^^^^^^^^^^^^^^^^^^^^^^^^^^^^^^^^^^
TypeError: get_user_pgns() missing 1 required positional argument: 'date'
2024-12-18 02:55:38.295234
Traceback (most recent call last):
  File "C:\Users\CFO Tech\source\repos\lucaschess\lucaschessR6\bin\Code\MainWindow\WBase.py", line 370, in run_action
    self.manager.run_action(self.sender().key)
  File "C:\Users\CFO Tech\source\repos\lucaschess\lucaschessR6\bin\Code\Procesador.py", line 583, in run_action
    self.menu_tools()
  File "C:\Users\CFO Tech\source\repos\lucaschess\lucaschessR6\bin\Code\Procesador.py", line 825, in menu_tools
    self.menuTools_run(resp)
  File "C:\Users\CFO Tech\source\repos\lucaschess\lucaschessR6\bin\Code\Procesador.py", line 861, in menuTools_run
    self.visor_remote_pgn()
  File "C:\Users\CFO Tech\source\repos\lucaschess\lucaschessR6\bin\Code\Procesador.py", line 1056, in visor_remote_pgn
    json_pgns = ChessDotComService.get_user_pgns(user_name,date)
                ^^^^^^^^^^^^^^^^^^^^^^^^^^^^^^^^
AttributeError: module 'Code.Services.ChessDotComService' has no attribute 'get_user_pgns'
2024-12-18 03:00:57.470445
Traceback (most recent call last):
  File "C:\Users\CFO Tech\source\repos\lucaschess\lucaschessR6\bin\Code\MainWindow\WBase.py", line 370, in run_action
    self.manager.run_action(self.sender().key)
  File "C:\Users\CFO Tech\source\repos\lucaschess\lucaschessR6\bin\Code\Procesador.py", line 583, in run_action
    self.menu_tools()
  File "C:\Users\CFO Tech\source\repos\lucaschess\lucaschessR6\bin\Code\Procesador.py", line 825, in menu_tools
    self.menuTools_run(resp)
  File "C:\Users\CFO Tech\source\repos\lucaschess\lucaschessR6\bin\Code\Procesador.py", line 861, in menuTools_run
    self.visor_remote_pgn()
  File "C:\Users\CFO Tech\source\repos\lucaschess\lucaschessR6\bin\Code\Procesador.py", line 1056, in visor_remote_pgn
    json_pgns = ChessDotCom.ChessDotComService.get_user_pgns(user_name,date)
                ^^^^^^^^^^^^^^^^^^^^^^^^^^^^^^^^^^^^^^^^^^^^^^^^^^^^^^^^^^^^
TypeError: ChessDotComService.get_user_pgns() missing 1 required positional argument: 'date'
2024-12-18 03:04:39.037155
Traceback (most recent call last):
  File "C:\Users\CFO Tech\source\repos\lucaschess\lucaschessR6\bin\Code\MainWindow\WBase.py", line 370, in run_action
    self.manager.run_action(self.sender().key)
  File "C:\Users\CFO Tech\source\repos\lucaschess\lucaschessR6\bin\Code\Procesador.py", line 583, in run_action
    self.menu_tools()
  File "C:\Users\CFO Tech\source\repos\lucaschess\lucaschessR6\bin\Code\Procesador.py", line 825, in menu_tools
    self.menuTools_run(resp)
  File "C:\Users\CFO Tech\source\repos\lucaschess\lucaschessR6\bin\Code\Procesador.py", line 861, in menuTools_run
    self.visor_remote_pgn()
  File "C:\Users\CFO Tech\source\repos\lucaschess\lucaschessR6\bin\Code\Procesador.py", line 1057, in visor_remote_pgn
    json_pgns = chess.get_user_pgns(user_name,date)
                ^^^^^^^^^^^^^^^^^^^^^^^^^^^^^^^^^^^
  File "C:\Users\CFO Tech\source\repos\lucaschess\lucaschessR6\bin\Code\Services\ChessDotCom.py", line 40, in get_user_pgns
    url = f"{self.base_url}/player/{username}/games/{date.year}/{date.moth}/pgn"
                                                                 ^^^^^^^^^
AttributeError: 'datetime.datetime' object has no attribute 'moth'. Did you mean: 'month'?
2024-12-18 03:08:42.777841
Traceback (most recent call last):
  File "C:\Users\CFO Tech\source\repos\lucaschess\lucaschessR6\bin\Code\MainWindow\WBase.py", line 370, in run_action
    self.manager.run_action(self.sender().key)
  File "C:\Users\CFO Tech\source\repos\lucaschess\lucaschessR6\bin\Code\Procesador.py", line 583, in run_action
    self.menu_tools()
  File "C:\Users\CFO Tech\source\repos\lucaschess\lucaschessR6\bin\Code\Procesador.py", line 825, in menu_tools
    self.menuTools_run(resp)
  File "C:\Users\CFO Tech\source\repos\lucaschess\lucaschessR6\bin\Code\Procesador.py", line 861, in menuTools_run
    self.visor_remote_pgn()
  File "C:\Users\CFO Tech\source\repos\lucaschess\lucaschessR6\bin\Code\Procesador.py", line 1059, in visor_remote_pgn
    self.read_remote_pgn(json_pgns,user_name,date)
  File "C:\Users\CFO Tech\source\repos\lucaschess\lucaschessR6\bin\Code\Procesador.py", line 999, in read_remote_pgn
    self.save_pgns(fichero_pgn, cfecha_pgn)
  File "C:\Users\CFO Tech\source\repos\lucaschess\lucaschessR6\bin\Code\Procesador.py", line 1037, in save_pgns
    db = DBgames.DBgames(file_db)
         ^^^^^^^^^^^^^^^^^^^^^^^^
  File "C:\Users\CFO Tech\source\repos\lucaschess\lucaschessR6\bin\Code\Databases\DBgames.py", line 48, in __init__
    self.conexion = sqlite3.connect(self.path_file)
                    ^^^^^^^^^^^^^^^^^^^^^^^^^^^^^^^
sqlite3.OperationalError: unable to open database file
2024-12-18 03:11:04.429836
Traceback (most recent call last):
  File "C:\Users\CFO Tech\source\repos\lucaschess\lucaschessR6\bin\Code\MainWindow\WBase.py", line 370, in run_action
    self.manager.run_action(self.sender().key)
  File "C:\Users\CFO Tech\source\repos\lucaschess\lucaschessR6\bin\Code\Procesador.py", line 583, in run_action
    self.menu_tools()
  File "C:\Users\CFO Tech\source\repos\lucaschess\lucaschessR6\bin\Code\Procesador.py", line 825, in menu_tools
    self.menuTools_run(resp)
  File "C:\Users\CFO Tech\source\repos\lucaschess\lucaschessR6\bin\Code\Procesador.py", line 861, in menuTools_run
    self.visor_remote_pgn()
  File "C:\Users\CFO Tech\source\repos\lucaschess\lucaschessR6\bin\Code\Procesador.py", line 1060, in visor_remote_pgn
    self.read_remote_pgn(json_pgns,user_name,date)
  File "C:\Users\CFO Tech\source\repos\lucaschess\lucaschessR6\bin\Code\Procesador.py", line 999, in read_remote_pgn
    self.save_pgns(fichero_pgn, cfecha_pgn)
  File "C:\Users\CFO Tech\source\repos\lucaschess\lucaschessR6\bin\Code\Procesador.py", line 1038, in save_pgns
    db = DBgames.DBgames(file_db)
         ^^^^^^^^^^^^^^^^^^^^^^^^
  File "C:\Users\CFO Tech\source\repos\lucaschess\lucaschessR6\bin\Code\Databases\DBgames.py", line 48, in __init__
    self.conexion = sqlite3.connect(self.path_file)
                    ^^^^^^^^^^^^^^^^^^^^^^^^^^^^^^^
sqlite3.OperationalError: unable to open database file
2024-12-18 03:12:53.538874
Traceback (most recent call last):
  File "C:\Users\CFO Tech\source\repos\lucaschess\lucaschessR6\bin\Code\MainWindow\WBase.py", line 370, in run_action
    self.manager.run_action(self.sender().key)
  File "C:\Users\CFO Tech\source\repos\lucaschess\lucaschessR6\bin\Code\Procesador.py", line 583, in run_action
    self.menu_tools()
  File "C:\Users\CFO Tech\source\repos\lucaschess\lucaschessR6\bin\Code\Procesador.py", line 825, in menu_tools
    self.menuTools_run(resp)
  File "C:\Users\CFO Tech\source\repos\lucaschess\lucaschessR6\bin\Code\Procesador.py", line 861, in menuTools_run
    self.visor_remote_pgn()
  File "C:\Users\CFO Tech\source\repos\lucaschess\lucaschessR6\bin\Code\Procesador.py", line 1060, in visor_remote_pgn
    self.read_remote_pgn(json_pgns,user_name,date)
  File "C:\Users\CFO Tech\source\repos\lucaschess\lucaschessR6\bin\Code\Procesador.py", line 999, in read_remote_pgn
    self.save_pgns(fichero_pgn, cfecha_pgn)
  File "C:\Users\CFO Tech\source\repos\lucaschess\lucaschessR6\bin\Code\Procesador.py", line 1038, in save_pgns
    db = DBgames.DBgames(file_db)
         ^^^^^^^^^^^^^^^^^^^^^^^^
  File "C:\Users\CFO Tech\source\repos\lucaschess\lucaschessR6\bin\Code\Databases\DBgames.py", line 48, in __init__
    self.conexion = sqlite3.connect(self.path_file)
                    ^^^^^^^^^^^^^^^^^^^^^^^^^^^^^^^
sqlite3.OperationalError: unable to open database file
2024-12-18 03:15:15.901149
Traceback (most recent call last):
  File "C:\Users\CFO Tech\source\repos\lucaschess\lucaschessR6\bin\Code\MainWindow\WBase.py", line 370, in run_action
    self.manager.run_action(self.sender().key)
  File "C:\Users\CFO Tech\source\repos\lucaschess\lucaschessR6\bin\Code\Procesador.py", line 583, in run_action
    self.menu_tools()
  File "C:\Users\CFO Tech\source\repos\lucaschess\lucaschessR6\bin\Code\Procesador.py", line 825, in menu_tools
    self.menuTools_run(resp)
  File "C:\Users\CFO Tech\source\repos\lucaschess\lucaschessR6\bin\Code\Procesador.py", line 861, in menuTools_run
    self.visor_remote_pgn()
  File "C:\Users\CFO Tech\source\repos\lucaschess\lucaschessR6\bin\Code\Procesador.py", line 1060, in visor_remote_pgn
    self.read_remote_pgn(json_pgns,user_name,date)
  File "C:\Users\CFO Tech\source\repos\lucaschess\lucaschessR6\bin\Code\Procesador.py", line 999, in read_remote_pgn
    self.save_pgns(fichero_pgn, cfecha_pgn)
  File "C:\Users\CFO Tech\source\repos\lucaschess\lucaschessR6\bin\Code\Procesador.py", line 1038, in save_pgns
    db = DBgames.DBgames(file_db)
         ^^^^^^^^^^^^^^^^^^^^^^^^
  File "C:\Users\CFO Tech\source\repos\lucaschess\lucaschessR6\bin\Code\Databases\DBgames.py", line 48, in __init__
    self.conexion = sqlite3.connect(self.path_file)
                    ^^^^^^^^^^^^^^^^^^^^^^^^^^^^^^^
sqlite3.OperationalError: unable to open database file
2024-12-18 03:16:43.111921
Traceback (most recent call last):
  File "C:\Users\CFO Tech\source\repos\lucaschess\lucaschessR6\bin\Code\MainWindow\WBase.py", line 370, in run_action
    self.manager.run_action(self.sender().key)
  File "C:\Users\CFO Tech\source\repos\lucaschess\lucaschessR6\bin\Code\Procesador.py", line 583, in run_action
    self.menu_tools()
  File "C:\Users\CFO Tech\source\repos\lucaschess\lucaschessR6\bin\Code\Procesador.py", line 825, in menu_tools
    self.menuTools_run(resp)
  File "C:\Users\CFO Tech\source\repos\lucaschess\lucaschessR6\bin\Code\Procesador.py", line 861, in menuTools_run
    self.visor_remote_pgn()
  File "C:\Users\CFO Tech\source\repos\lucaschess\lucaschessR6\bin\Code\Procesador.py", line 1061, in visor_remote_pgn
    self.read_remote_pgn(json_pgns,user_name,date)
  File "C:\Users\CFO Tech\source\repos\lucaschess\lucaschessR6\bin\Code\Procesador.py", line 999, in read_remote_pgn
    self.save_pgns(fichero_pgn, cfecha_pgn)
  File "C:\Users\CFO Tech\source\repos\lucaschess\lucaschessR6\bin\Code\Procesador.py", line 1039, in save_pgns
    db = DBgames.DBgames(file_db)
         ^^^^^^^^^^^^^^^^^^^^^^^^
  File "C:\Users\CFO Tech\source\repos\lucaschess\lucaschessR6\bin\Code\Databases\DBgames.py", line 48, in __init__
    self.conexion = sqlite3.connect(self.path_file)
                    ^^^^^^^^^^^^^^^^^^^^^^^^^^^^^^^
sqlite3.OperationalError: unable to open database file
2024-12-18 03:18:51.142369
Traceback (most recent call last):
  File "C:\Users\CFO Tech\source\repos\lucaschess\lucaschessR6\bin\Code\MainWindow\WBase.py", line 370, in run_action
    self.manager.run_action(self.sender().key)
  File "C:\Users\CFO Tech\source\repos\lucaschess\lucaschessR6\bin\Code\Procesador.py", line 583, in run_action
    self.menu_tools()
  File "C:\Users\CFO Tech\source\repos\lucaschess\lucaschessR6\bin\Code\Procesador.py", line 825, in menu_tools
    self.menuTools_run(resp)
  File "C:\Users\CFO Tech\source\repos\lucaschess\lucaschessR6\bin\Code\Procesador.py", line 861, in menuTools_run
    self.visor_remote_pgn()
  File "C:\Users\CFO Tech\source\repos\lucaschess\lucaschessR6\bin\Code\Procesador.py", line 1060, in visor_remote_pgn
    self.read_remote_pgn(json_pgns,user_name,date)
  File "C:\Users\CFO Tech\source\repos\lucaschess\lucaschessR6\bin\Code\Procesador.py", line 999, in read_remote_pgn
    self.save_pgns(fichero_pgn, cfecha_pgn)
  File "C:\Users\CFO Tech\source\repos\lucaschess\lucaschessR6\bin\Code\Procesador.py", line 1038, in save_pgns
    db = DBgames.DBgames(file_db)
         ^^^^^^^^^^^^^^^^^^^^^^^^
  File "C:\Users\CFO Tech\source\repos\lucaschess\lucaschessR6\bin\Code\Databases\DBgames.py", line 48, in __init__
    self.conexion = sqlite3.connect(self.path_file)
                    ^^^^^^^^^^^^^^^^^^^^^^^^^^^^^^^
sqlite3.OperationalError: unable to open database file
2024-12-18 03:26:40.893542
Traceback (most recent call last):
  File "C:\Users\CFO Tech\source\repos\lucaschess\lucaschessR6\bin\Code\MainWindow\WBase.py", line 370, in run_action
    self.manager.run_action(self.sender().key)
  File "C:\Users\CFO Tech\source\repos\lucaschess\lucaschessR6\bin\Code\Procesador.py", line 583, in run_action
    self.menu_tools()
  File "C:\Users\CFO Tech\source\repos\lucaschess\lucaschessR6\bin\Code\Procesador.py", line 825, in menu_tools
    self.menuTools_run(resp)
  File "C:\Users\CFO Tech\source\repos\lucaschess\lucaschessR6\bin\Code\Procesador.py", line 861, in menuTools_run
    self.visor_remote_pgn()
  File "C:\Users\CFO Tech\source\repos\lucaschess\lucaschessR6\bin\Code\Procesador.py", line 1064, in visor_remote_pgn
    self.read_remote_pgn(json_pgns,user_name,date)
  File "C:\Users\CFO Tech\source\repos\lucaschess\lucaschessR6\bin\Code\Procesador.py", line 999, in read_remote_pgn
    with open(fichero_pgn, "wt", encoding="utf-8", errors="ignore") as q:
         ^^^^^^^^^^^^^^^^^^^^^^^^^^^^^^^^^^^^^^^^^^^^^^^^^^^^^^^^^^
OSError: [Errno 22] Invalid argument: 'C:\\Users\\CFO Tech\\source\\repos\\lucaschess\\lucaschessR6\\bin\\cmess4401_2024-12-18 03:26:22.068888.pgn'
2024-12-18 03:28:10.252571
Traceback (most recent call last):
  File "C:\Users\CFO Tech\source\repos\lucaschess\lucaschessR6\bin\Code\MainWindow\WBase.py", line 370, in run_action
    self.manager.run_action(self.sender().key)
  File "C:\Users\CFO Tech\source\repos\lucaschess\lucaschessR6\bin\Code\Procesador.py", line 583, in run_action
    self.menu_tools()
  File "C:\Users\CFO Tech\source\repos\lucaschess\lucaschessR6\bin\Code\Procesador.py", line 825, in menu_tools
    self.menuTools_run(resp)
  File "C:\Users\CFO Tech\source\repos\lucaschess\lucaschessR6\bin\Code\Procesador.py", line 861, in menuTools_run
    self.visor_remote_pgn()
  File "C:\Users\CFO Tech\source\repos\lucaschess\lucaschessR6\bin\Code\Procesador.py", line 1065, in visor_remote_pgn
    self.read_remote_pgn(json_pgns,user_name,date)
  File "C:\Users\CFO Tech\source\repos\lucaschess\lucaschessR6\bin\Code\Procesador.py", line 1001, in read_remote_pgn
    with open(fichero_pgn, "wt", encoding="utf-8", errors="ignore") as q:
         ^^^^^^^^^^^^^^^^^^^^^^^^^^^^^^^^^^^^^^^^^^^^^^^^^^^^^^^^^^
FileNotFoundError: [Errno 2] No such file or directory: 'C_\\Users\\CFO_Tech\\source\\repos\\lucaschess\\lucaschessR6\\bin\\cmess4401_2024-12-18_03_27_50.730537.pgn'
2024-12-18 03:30:51.321414
Traceback (most recent call last):
  File "C:\Users\CFO Tech\source\repos\lucaschess\lucaschessR6\bin\Code\MainWindow\WBase.py", line 370, in run_action
    self.manager.run_action(self.sender().key)
  File "C:\Users\CFO Tech\source\repos\lucaschess\lucaschessR6\bin\Code\Procesador.py", line 583, in run_action
    self.menu_tools()
  File "C:\Users\CFO Tech\source\repos\lucaschess\lucaschessR6\bin\Code\Procesador.py", line 825, in menu_tools
    self.menuTools_run(resp)
  File "C:\Users\CFO Tech\source\repos\lucaschess\lucaschessR6\bin\Code\Procesador.py", line 861, in menuTools_run
    self.visor_remote_pgn()
  File "C:\Users\CFO Tech\source\repos\lucaschess\lucaschessR6\bin\Code\Procesador.py", line 1065, in visor_remote_pgn
    self.read_remote_pgn(json_pgns,user_name,date)
  File "C:\Users\CFO Tech\source\repos\lucaschess\lucaschessR6\bin\Code\Procesador.py", line 1001, in read_remote_pgn
    with open(fichero_pgn, "w") as q:
         ^^^^^^^^^^^^^^^^^^^^^^
FileNotFoundError: [Errno 2] No such file or directory: 'C_\\Users\\CFO_Tech\\source\\repos\\lucaschess\\lucaschessR6\\bin\\cmess4401_2024-12-18_03_30_45.219831.pgn'
2024-12-18 14:58:44.298240
Traceback (most recent call last):
  File "C:\Users\CFO Tech\source\repos\lucaschess\lucaschessR6\bin\Code\MainWindow\WBase.py", line 370, in run_action
    self.manager.run_action(self.sender().key)
  File "C:\Users\CFO Tech\source\repos\lucaschess\lucaschessR6\bin\Code\Procesador.py", line 584, in run_action
    self.menu_tools()
  File "C:\Users\CFO Tech\source\repos\lucaschess\lucaschessR6\bin\Code\Procesador.py", line 830, in menu_tools
    self.menuTools_run(resp)
  File "C:\Users\CFO Tech\source\repos\lucaschess\lucaschessR6\bin\Code\Procesador.py", line 866, in menuTools_run
    self.visor_remote_pgn()
  File "C:\Users\CFO Tech\source\repos\lucaschess\lucaschessR6\bin\Code\Procesador.py", line 1066, in visor_remote_pgn
    user_name = self.set_chesscom_configuration()
                ^^^^^^^^^^^^^^^^^^^^^^^^^^^^^^^^^
  File "C:\Users\CFO Tech\source\repos\lucaschess\lucaschessR6\bin\Code\Procesador.py", line 790, in set_chesscom_configuration
    user, date = WindowChessCom.WChessCom(self)
                 ^^^^^^^^^^^^^^^^^^^^^^^^^^^^^^
  File "C:\Users\CFO Tech\source\repos\lucaschess\lucaschessR6\bin\Code\Services\WindowChessCom.py", line 30, in __init__
    (_("New"), Iconos.Nuevo(), self.nuevo),
                               ^^^^^^^^^^
AttributeError: 'WChessCom' object has no attribute 'nuevo'
2024-12-18 18:08:11.899755
Traceback (most recent call last):
  File "C:\Users\CFO Tech\source\repos\lucaschess\lucaschessR6\bin\Code\MainWindow\WBase.py", line 370, in run_action
    self.manager.run_action(self.sender().key)
  File "C:\Users\CFO Tech\source\repos\lucaschess\lucaschessR6\bin\Code\Procesador.py", line 584, in run_action
    self.menu_tools()
  File "C:\Users\CFO Tech\source\repos\lucaschess\lucaschessR6\bin\Code\Procesador.py", line 830, in menu_tools
    self.menuTools_run(resp)
  File "C:\Users\CFO Tech\source\repos\lucaschess\lucaschessR6\bin\Code\Procesador.py", line 866, in menuTools_run
    self.visor_remote_pgn()
  File "C:\Users\CFO Tech\source\repos\lucaschess\lucaschessR6\bin\Code\Procesador.py", line 1066, in visor_remote_pgn
    user_name = self.set_chesscom_configuration()
                ^^^^^^^^^^^^^^^^^^^^^^^^^^^^^^^^^
  File "C:\Users\CFO Tech\source\repos\lucaschess\lucaschessR6\bin\Code\Procesador.py", line 790, in set_chesscom_configuration
    user, date = WindowChessCom.WChessCom(self)
                 ^^^^^^^^^^^^^^^^^^^^^^^^^^^^^^
  File "C:\Users\CFO Tech\source\repos\lucaschess\lucaschessR6\bin\Code\Services\WindowChessCom.py", line 30, in __init__
    (_("New"), Iconos.Nuevo(), self.nuevo),
                               ^^^^^^^^^^
AttributeError: 'WChessCom' object has no attribute 'nuevo'
2024-12-18 19:03:27.451194
Traceback (most recent call last):
  File "C:\Users\CFO Tech\source\repos\lucaschess\lucaschessR6\bin\Code\MainWindow\WBase.py", line 370, in run_action
    self.manager.run_action(self.sender().key)
  File "C:\Users\CFO Tech\source\repos\lucaschess\lucaschessR6\bin\Code\Procesador.py", line 584, in run_action
    self.menu_tools()
  File "C:\Users\CFO Tech\source\repos\lucaschess\lucaschessR6\bin\Code\Procesador.py", line 830, in menu_tools
    self.menuTools_run(resp)
  File "C:\Users\CFO Tech\source\repos\lucaschess\lucaschessR6\bin\Code\Procesador.py", line 866, in menuTools_run
    self.visor_remote_pgn()
  File "C:\Users\CFO Tech\source\repos\lucaschess\lucaschessR6\bin\Code\Procesador.py", line 1066, in visor_remote_pgn
    user_name = self.set_chesscom_configuration()
                ^^^^^^^^^^^^^^^^^^^^^^^^^^^^^^^^^
  File "C:\Users\CFO Tech\source\repos\lucaschess\lucaschessR6\bin\Code\Procesador.py", line 790, in set_chesscom_configuration
    user, date = WindowChessCom.WChessCom(self)
                 ^^^^^^^^^^^^^^^^^^^^^^^^^^^^^^
  File "C:\Users\CFO Tech\source\repos\lucaschess\lucaschessR6\bin\Code\Services\WindowChessCom.py", line 30, in __init__
    (_("New"), Iconos.Nuevo(), self.nuevo),
                               ^^^^^^^^^^
AttributeError: 'WChessCom' object has no attribute 'nuevo'
